Workbook

Sheet CH1-CH8
E1: TỔNG CÔNG TY CÔNG NGHIỆP CÔNG NGHỆ CAO VIETTEL | M1: Mã dự án:
E2: KHỐI 2 - TRUNG TÂM NGHIÊN CỨU THIẾT BỊ VÔ TUYẾN BĂNG RỘNG | M2: Tài liệu HDĐK:
M3: Mã sản phẩm:
E4: PHIẾU ĐO KIỂM | M4: Mã mẫu: | N4: 32T32R
A5: Thông tin về máy đo, dụng cụ đo | E5: VSA: | F5: N9020A | I5: S/N: | L5: Hạn kiểm định: | M5: 2023
E6: VSG: | F6: N5182B | I6: S/N: | J6: MY57300543 | L6: Hạn kiểm định: | M6: 2023
E7: BBU: | F7: SUPERMICRO195 | I7: Type: | J7: Xeon D | L7: FW Version:
E8: RRU: | F8: 32T32R | I8: ID. No.: | J8: 31 | L8: FW Version: | M8: 3.4.10
E9: FREQ (MHz) | F9: 2550 | I9: BW (MHz) | J9: 100 | L9: FPGA Version:
A10: Thông tin điều kiện thực hiện | E10: Địa điểm: | F10: Phòng Lab EnodeB, tầng 13, Tòa nhà Viettel Hòa Lạc
E11: Môi trường: | F11: Phòng LAB | I11: Nhiệt độ: | L11: Độ ẩm:
E12: Thời gian: | F12: Từ: | I12: Đến: | L12: Tổng thời gian:
A13: STT | B13: THAM SỐ ĐO ĐẠC | E13: ĐƠN VỊ | F13: GIÁ TRỊ YÊU CẦU | J13: GIÁ TRỊ ĐO | L13: TIÊU CHUẨN THAM CHIẾU | M13: ĐÁNH GIÁ | N13: GHI CHÚ
F14: NR-TM | G14: SPECS | H14: MIN | I14: MAX
A15: I | B15: Conducted Transmitter Characteristics
A16: 1.1 | B16: Base station output power | E16: dBm | F16: TM1.1 | G16: 40 | H16: 37.3 | I16: 42.7 | J16: PORT1 | K16: =VLOOKUP($B$16&J16&$F$16,TXRESULT!$A$1:$J$1004,6,FALSE) -> 40.1 | L16: TS 38.141 / Chapter 6.2: Base station output power | M16: =IF(ISBLANK(K16),"",IF(AND(K16*1>H16*1,K16*1<I16*1),"PASS","FAIL")) -> PASS | N16: =IF(ISBLANK(K16),"CHUADO","")
G17: 40 | H17: 37.3 | I17: 42.7 | J17: PORT2 | K17: =VLOOKUP($B$16&J17&$F$16,TXRESULT!$A$1:$J$1004,6,FALSE) -> 40.3 | M17: =IF(ISBLANK(K17),"",IF(AND(K17*1>H17*1,K17*1<I17*1),"PASS","FAIL")) -> PASS | N17: =IF(ISBLANK(K17),"CHUADO","")
G18: 40 | H18: 37.3 | I18: 42.7 | J18: PORT3 | K18: =VLOOKUP($B$16&J18&$F$16,TXRESULT!$A$1:$J$1004,6,FALSE) -> 40.1 | M18: =IF(ISBLANK(K18),"",IF(AND(K18*1>H18*1,K18*1<I18*1),"PASS","FAIL")) -> PASS | N18: =IF(ISBLANK(K18),"CHUADO","")
G19: 40 | H19: 37.3 | I19: 42.7 | J19: PORT4 | K19: =VLOOKUP($B$16&J19&$F$16,TXRESULT!$A$1:$J$1004,6,FALSE) -> 40.1 | M19: =IF(ISBLANK(K19),"",IF(AND(K19*1>H19*1,K19*1<I19*1),"PASS","FAIL")) -> PASS | N19: =IF(ISBLANK(K19),"CHUADO","")
G20: 40 | H20: 37.3 | I20: 42.7 | J20: PORT5 | K20: =VLOOKUP($B$16&J20&$F$16,TXRESULT!$A$1:$J$1004,6,FALSE) -> 39.6 | M20: =IF(ISBLANK(K20),"",IF(AND(K20*1>H20*1,K20*1<I20*1),"PASS","FAIL")) -> PASS | N20: =IF(ISBLANK(K20),"CHUADO","")
G21: 40 | H21: 37.3 | I21: 42.7 | J21: PORT6 | K21: =VLOOKUP($B$16&J21&$F$16,TXRESULT!$A$1:$J$1004,6,FALSE) -> 39.9 | M21: =IF(ISBLANK(K21),"",IF(AND(K21*1>H21*1,K21*1<I21*1),"PASS","FAIL")) -> PASS | N21: =IF(ISBLANK(K21),"CHUADO","")
G22: 40 | H22: 37.3 | I22: 42.7 | J22: PORT7 | K22: =VLOOKUP($B$16&J22&$F$16,TXRESULT!$A$1:$J$1004,6,FALSE) -> 39.9 | M22: =IF(ISBLANK(K22),"",IF(AND(K22*1>H22*1,K22*1<I22*1),"PASS","FAIL")) -> PASS | N22: =IF(ISBLANK(K22),"CHUADO","")
G23: 40 | H23: 37.3 | I23: 42.7 | J23: PORT8 | K23: =VLOOKUP($B$16&J23&$F$16,TXRESULT!$A$1:$J$1004,6,FALSE) -> 39.8 | M23: =IF(ISBLANK(K23),"",IF(AND(K23*1>H23*1,K23*1<I23*1),"PASS","FAIL")) -> PASS | N23: =IF(ISBLANK(K23),"CHUADO","")
B24: Output Power Dynamic | E24: =IF(OR(K24="",AND(H24="",I24="")),"",IF(OR(AND(K24<>"",I24<>"",K24>I24),AND(K24<>"",H24<>"",K24<H24)),"FAIL","PASS"))
A25: 1.2 | B25: Total power dynamic range | E25: dB | F25: TM2.0a TM3.1a | G25: 23.9 | H25: =G25 -> 23.9 | I25: =IF(ISBLANK('[1]CH1-CH8'!G11),"",('[1]CH1-CH8'!G11)) | J25: PORT1 | K25: =VLOOKUP($B$25&J25&$F$25,TXRESULT!$A$1:$J$1004,6,FALSE) -> 26.2 | L25: TS 38.141 / Chapter 6.3.3: Total power dynamic range / 30 kHz SCS | M25: =IF(ISBLANK(K25),"",IF(AND(K25*1>H25*1),"PASS","FAIL")) -> PASS | N25: =IF(ISBLANK(K25),"CHUADO","")
G26: =G25 -> 23.9 | H26: =H25 -> 23.9 | I26: =I25 | J26: PORT2 | K26: =VLOOKUP($B$25&J26&$F$25,TXRESULT!$A$1:$J$1004,6,FALSE) -> 26 | M26: =IF(ISBLANK(K26),"",IF(AND(K26*1>H26*1),"PASS","FAIL")) -> PASS | N26: =IF(ISBLANK(K26),"CHUADO","")
G27: =G25 -> 23.9 | H27: =H25 -> 23.9 | I27: =I25 | J27: PORT3 | K27: =VLOOKUP($B$25&J27&$F$25,TXRESULT!$A$1:$J$1004,6,FALSE) -> 26.2 | M27: =IF(ISBLANK(K27),"",IF(AND(K27*1>H27*1),"PASS","FAIL")) -> PASS | N27: =IF(ISBLANK(K27),"CHUADO","")
G28: =G25 -> 23.9 | H28: =H25 -> 23.9 | I28: =I25 | J28: PORT4 | K28: =VLOOKUP($B$25&J28&$F$25,TXRESULT!$A$1:$J$1004,6,FALSE) -> 26.3 | M28: =IF(ISBLANK(K28),"",IF(AND(K28*1>H28*1),"PASS","FAIL")) -> PASS | N28: =IF(ISBLANK(K28),"CHUADO","")
G29: =G25 -> 23.9 | H29: =H25 -> 23.9 | I29: =I25 | J29: PORT5 | K29: =VLOOKUP($B$25&J29&$F$25,TXRESULT!$A$1:$J$1004,6,FALSE) -> 26.5 | M29: =IF(ISBLANK(K29),"",IF(AND(K29*1>H29*1),"PASS","FAIL")) -> PASS | N29: =IF(ISBLANK(K29),"CHUADO","")
G30: =G25 -> 23.9 | H30: =H25 -> 23.9 | I30: =I25 | J30: PORT6 | K30: =VLOOKUP($B$25&J30&$F$25,TXRESULT!$A$1:$J$1004,6,FALSE) -> 25.8 | M30: =IF(ISBLANK(K30),"",IF(AND(K30*1>H30*1),"PASS","FAIL")) -> PASS | N30: =IF(ISBLANK(K30),"CHUADO","")
G31: =G25 -> 23.9 | H31: =H25 -> 23.9 | I31: =I25 | J31: PORT7 | K31: =VLOOKUP($B$25&J31&$F$25,TXRESULT!$A$1:$J$1004,6,FALSE) -> 26.2 | M31: =IF(ISBLANK(K31),"",IF(AND(K31*1>H31*1),"PASS","FAIL")) -> PASS | N31: =IF(ISBLANK(K31),"CHUADO","")
G32: =G25 -> 23.9 | H32: =H25 -> 23.9 | I32: =I25 | J32: PORT8 | K32: =VLOOKUP($B$25&J32&$F$25,TXRESULT!$A$1:$J$1004,6,FALSE) -> 25.9 | M32: =IF(ISBLANK(K32),"",IF(AND(K32*1>H32*1),"PASS","FAIL")) -> PASS | N32: =IF(ISBLANK(K32),"CHUADO","")
B33: TX Transmittion ON/OFF Power | M33: =IF(ISBLANK(K33),"",IF(AND(K33*1>H33*1),"PASS","FAIL"))
A34: 1.3 | B34: Transmitter OFF power | E34: dBm/ MHz | F34: TM1.1 | G34: -82.5 | H34: =IF(ISBLANK('[1]CH1-CH8'!F17),"",('[1]CH1-CH8'!F17)) | I34: -82.5 | J34: PORT1 | K34: =VLOOKUP($B$34&J34&$F$34,TXRESULT!$A$1:$J$1004,6,FALSE) -> #N/A | L34: TS 38.141 / Chapter 6.4.1: Transmitter OFF power/ 6.4.1.3 | M34: =IF(ISBLANK(K34),"",IF(AND(K34*1<I34*1),"PASS","FAIL")) -> #N/A | N34: =IF(ISBLANK(K34),"CHUADO","")
G35: =G34 -> -82.5 | H35: =H34 | I35: =I34 -> -82.5 | J35: PORT2 | K35: =VLOOKUP($B$34&J35&$F$34,TXRESULT!$A$1:$J$1004,6,FALSE) -> #N/A | M35: =IF(ISBLANK(K35),"",IF(AND(K35*1<I35*1),"PASS","FAIL")) -> #N/A | N35: =IF(ISBLANK(K35),"CHUADO","")
G36: =G34 -> -82.5 | H36: =H34 | I36: =I34 -> -82.5 | J36: PORT3 | K36: =VLOOKUP($B$34&J36&$F$34,TXRESULT!$A$1:$J$1004,6,FALSE) -> #N/A | M36: =IF(ISBLANK(K36),"",IF(AND(K36*1<I36*1),"PASS","FAIL")) -> #N/A | N36: =IF(ISBLANK(K36),"CHUADO","")
G37: =G34 -> -82.5 | H37: =H34 | I37: =I34 -> -82.5 | J37: PORT4 | K37: =VLOOKUP($B$34&J37&$F$34,TXRESULT!$A$1:$J$1004,6,FALSE) -> #N/A | M37: =IF(ISBLANK(K37),"",IF(AND(K37*1<I37*1),"PASS","FAIL")) -> #N/A | N37: =IF(ISBLANK(K37),"CHUADO","")
G38: =G34 -> -82.5 | H38: =H34 | I38: =I34 -> -82.5 | J38: PORT5 | K38: =VLOOKUP($B$34&J38&$F$34,TXRESULT!$A$1:$J$1004,6,FALSE) -> #N/A | M38: =IF(ISBLANK(K38),"",IF(AND(K38*1<I38*1),"PASS","FAIL")) -> #N/A | N38: =IF(ISBLANK(K38),"CHUADO","")
G39: =G34 -> -82.5 | H39: =H34 | I39: =I34 -> -82.5 | J39: PORT6 | K39: =VLOOKUP($B$34&J39&$F$34,TXRESULT!$A$1:$J$1004,6,FALSE) -> #N/A | M39: =IF(ISBLANK(K39),"",IF(AND(K39*1<I39*1),"PASS","FAIL")) -> #N/A | N39: =IF(ISBLANK(K39),"CHUADO","")
G40: =G34 -> -82.5 | H40: =H34 | I40: =I34 -> -82.5 | J40: PORT7 | K40: =VLOOKUP($B$34&J40&$F$34,TXRESULT!$A$1:$J$1004,6,FALSE) -> #N/A | M40: =IF(ISBLANK(K40),"",IF(AND(K40*1<I40*1),"PASS","FAIL")) -> #N/A | N40: =IF(ISBLANK(K40),"CHUADO","")
...

Sheet CH9-CH16
E1: TỔNG CÔNG TY CÔNG NGHIỆP CÔNG NGHỆ CAO VIETTEL | M1: Mã dự án:
E2: KHỐI 2 - TRUNG TÂM NGHIÊN CỨU THIẾT BỊ VÔ TUYẾN BĂNG RỘNG | M2: Tài liệu HDĐK:
M3: Mã sản phẩm:
E4: PHIẾU ĐO KIỂM | M4: Mã mẫu: | N4: 32T32R
A5: Thông tin về máy đo, dụng cụ đo | E5: VSA: | F5: N9020A | I5: S/N: | L5: Hạn kiểm định: | M5: 2023
E6: VSG: | F6: N5182B | I6: S/N: | J6: MY57300543 | L6: Hạn kiểm định: | M6: 2023
E7: BBU: | F7: SUPERMICRO195 | I7: Type: | J7: Xeon D | L7: FW Version:
E8: RRU: | F8: 32T32R | I8: ID. No.: | J8: ='CH1-CH8'!$J$8 -> 31 | L8: FW Version: | M8: ='CH1-CH8'!M8 -> 3.4.10
E9: FREQ (MHz) | F9: 2550 | I9: BW (MHz) | J9: 100 | L9: FPGA Version:
A10: Thông tin điều kiện thực hiện | E10: Địa điểm: | F10: Phòng Lab EnodeB, tầng 13, Tòa nhà Viettel Hòa Lạc
E11: Môi trường: | F11: Phòng LAB | I11: Nhiệt độ: | L11: Độ ẩm:
E12: Thời gian: | F12: Từ: | I12: Đến: | L12: Tổng thời gian:
A13: STT | B13: THAM SỐ ĐO ĐẠC | E13: ĐƠN VỊ | F13: GIÁ TRỊ YÊU CẦU | J13: GIÁ TRỊ ĐO | L13: TIÊU CHUẨN THAM CHIẾU | M13: ĐÁNH GIÁ | N13: GHI CHÚ
F14: NR-TM | G14: SPECS | H14: MIN | I14: MAX
A15: I | B15: Conducted Transmitter Characteristics
A16: 1.1 | B16: Base station output power | E16: dBm | F16: TM1.1 | G16: 40 | H16: 37.3 | I16: 42.7 | J16: PORT9 | K16: =VLOOKUP($B$16&J16&$F$16,TXRESULT!$A$1:$J$1004,6,FALSE) -> 39.8 | L16: TS 38.141 / Chapter 6.2: Base station output power | M16: =IF(ISBLANK(K16),"",IF(AND(K16*1>H16*1,K16*1<I16*1),"PASS","FAIL")) -> PASS | N16: =IF(ISBLANK(K16),"CHUADO","")
G17: 40 | H17: 37.3 | I17: 42.7 | J17: PORT10 | K17: =VLOOKUP($B$16&J17&$F$16,TXRESULT!$A$1:$J$1004,6,FALSE) -> 39.5 | M17: =IF(ISBLANK(K17),"",IF(AND(K17*1>H17*1,K17*1<I17*1),"PASS","FAIL")) -> PASS | N17: =IF(ISBLANK(K17),"CHUADO","")
G18: 40 | H18: 37.3 | I18: 42.7 | J18: PORT11 | K18: =VLOOKUP($B$16&J18&$F$16,TXRESULT!$A$1:$J$1004,6,FALSE) -> 39.8 | M18: =IF(ISBLANK(K18),"",IF(AND(K18*1>H18*1,K18*1<I18*1),"PASS","FAIL")) -> PASS | N18: =IF(ISBLANK(K18),"CHUADO","")
G19: 40 | H19: 37.3 | I19: 42.7 | J19: PORT12 | K19: =VLOOKUP($B$16&J19&$F$16,TXRESULT!$A$1:$J$1004,6,FALSE) -> 39.6 | M19: =IF(ISBLANK(K19),"",IF(AND(K19*1>H19*1,K19*1<I19*1),"PASS","FAIL")) -> PASS | N19: =IF(ISBLANK(K19),"CHUADO","")
G20: 40 | H20: 37.3 | I20: 42.7 | J20: PORT13 | K20: =VLOOKUP($B$16&J20&$F$16,TXRESULT!$A$1:$J$1004,6,FALSE) -> 39.5 | M20: =IF(ISBLANK(K20),"",IF(AND(K20*1>H20*1,K20*1<I20*1),"PASS","FAIL")) -> PASS | N20: =IF(ISBLANK(K20),"CHUADO","")
G21: 40 | H21: 37.3 | I21: 42.7 | J21: PORT14 | K21: =VLOOKUP($B$16&J21&$F$16,TXRESULT!$A$1:$J$1004,6,FALSE) -> 39.8 | M21: =IF(ISBLANK(K21),"",IF(AND(K21*1>H21*1,K21*1<I21*1),"PASS","FAIL")) -> PASS | N21: =IF(ISBLANK(K21),"CHUADO","")
G22: 40 | H22: 37.3 | I22: 42.7 | J22: PORT15 | K22: =VLOOKUP($B$16&J22&$F$16,TXRESULT!$A$1:$J$1004,6,FALSE) -> 39.8 | M22: =IF(ISBLANK(K22),"",IF(AND(K22*1>H22*1,K22*1<I22*1),"PASS","FAIL")) -> PASS | N22: =IF(ISBLANK(K22),"CHUADO","")
G23: 40 | H23: 37.3 | I23: 42.7 | J23: PORT16 | K23: =VLOOKUP($B$16&J23&$F$16,TXRESULT!$A$1:$J$1004,6,FALSE) -> 39.9 | M23: =IF(ISBLANK(K23),"",IF(AND(K23*1>H23*1,K23*1<I23*1),"PASS","FAIL")) -> PASS | N23: =IF(ISBLANK(K23),"CHUADO","")
B24: Output Power Dynamic | E24: =IF(OR(K24="",AND(H24="",I24="")),"",IF(OR(AND(K24<>"",I24<>"",K24>I24),AND(K24<>"",H24<>"",K24<H24)),"FAIL","PASS"))
A25: 1.2 | B25: Total power dynamic range | E25: dB | F25: TM2.0a TM3.1a | G25: 23.9 | H25: =G25 -> 23.9 | I25: =IF(ISBLANK('[1]CH1-CH8'!G11),"",('[1]CH1-CH8'!G11)) | J25: PORT9 | K25: =VLOOKUP($B$25&J25&$F$25,TXRESULT!$A$1:$J$1004,6,FALSE) -> 26 | L25: TS 38.141 / Chapter 6.3.3: Total power dynamic range / 30 kHz SCS | M25: =IF(ISBLANK(K25),"",IF(AND(K25*1>H25*1),"PASS","FAIL")) -> PASS | N25: =IF(ISBLANK(K25),"CHUADO","")
G26: =G25 -> 23.9 | H26: =H25 -> 23.9 | I26: =I25 | J26: PORT10 | K26: =VLOOKUP($B$25&J26&$F$25,TXRESULT!$A$1:$J$1004,6,FALSE) -> 26.4 | M26: =IF(ISBLANK(K26),"",IF(AND(K26*1>H26*1),"PASS","FAIL")) -> PASS | N26: =IF(ISBLANK(K26),"CHUADO","")
G27: =G25 -> 23.9 | H27: =H25 -> 23.9 | I27: =I25 | J27: PORT11 | K27: =VLOOKUP($B$25&J27&$F$25,TXRESULT!$A$1:$J$1004,6,FALSE) -> 26.4 | M27: =IF(ISBLANK(K27),"",IF(AND(K27*1>H27*1),"PASS","FAIL")) -> PASS | N27: =IF(ISBLANK(K27),"CHUADO","")
G28: =G25 -> 23.9 | H28: =H25 -> 23.9 | I28: =I25 | J28: PORT12 | K28: =VLOOKUP($B$25&J28&$F$25,TXRESULT!$A$1:$J$1004,6,FALSE) -> 26.2 | M28: =IF(ISBLANK(K28),"",IF(AND(K28*1>H28*1),"PASS","FAIL")) -> PASS | N28: =IF(ISBLANK(K28),"CHUADO","")
G29: =G25 -> 23.9 | H29: =H25 -> 23.9 | I29: =I25 | J29: PORT13 | K29: =VLOOKUP($B$25&J29&$F$25,TXRESULT!$A$1:$J$1004,6,FALSE) -> 26.7 | M29: =IF(ISBLANK(K29),"",IF(AND(K29*1>H29*1),"PASS","FAIL")) -> PASS | N29: =IF(ISBLANK(K29),"CHUADO","")
G30: =G25 -> 23.9 | H30: =H25 -> 23.9 | I30: =I25 | J30: PORT14 | K30: =VLOOKUP($B$25&J30&$F$25,TXRESULT!$A$1:$J$1004,6,FALSE) -> 26.3 | M30: =IF(ISBLANK(K30),"",IF(AND(K30*1>H30*1),"PASS","FAIL")) -> PASS | N30: =IF(ISBLANK(K30),"CHUADO","")
G31: =G25 -> 23.9 | H31: =H25 -> 23.9 | I31: =I25 | J31: PORT15 | K31: =VLOOKUP($B$25&J31&$F$25,TXRESULT!$A$1:$J$1004,6,FALSE) -> 26.1 | M31: =IF(ISBLANK(K31),"",IF(AND(K31*1>H31*1),"PASS","FAIL")) -> PASS | N31: =IF(ISBLANK(K31),"CHUADO","")
G32: =G25 -> 23.9 | H32: =H25 -> 23.9 | I32: =I25 | J32: PORT16 | K32: =VLOOKUP($B$25&J32&$F$25,TXRESULT!$A$1:$J$1004,6,FALSE) -> 26.5 | M32: =IF(ISBLANK(K32),"",IF(AND(K32*1>H32*1),"PASS","FAIL")) -> PASS | N32: =IF(ISBLANK(K32),"CHUADO","")
B33: TX Transmittion ON/OFF Power | M33: =IF(ISBLANK(K33),"",IF(AND(K33*1>H33*1),"PASS","FAIL"))
A34: 1.3 | B34: Transmitter OFF power | E34: dBm/ MHz | F34: TM1.1 | G34: -82.5 | H34: =IF(ISBLANK('[1]CH1-CH8'!F17),"",('[1]CH1-CH8'!F17)) | I34: -82.5 | J34: PORT9 | K34: =VLOOKUP($B$34&J34&$F$34,TXRESULT!$A$1:$J$1004,6,FALSE) -> #N/A | L34: TS 38.141 / Chapter 6.4.1: Transmitter OFF power/ 6.4.1.3 | M34: =IF(ISBLANK(K34),"",IF(AND(K34*1<I34*1),"PASS","FAIL")) -> #N/A | N34: =IF(ISBLANK(K34),"CHUADO","")
G35: =G34 -> -82.5 | H35: =H34 | I35: =I34 -> -82.5 | J35: PORT10 | K35: =VLOOKUP($B$34&J35&$F$34,TXRESULT!$A$1:$J$1004,6,FALSE) -> #N/A | M35: =IF(ISBLANK(K35),"",IF(AND(K35*1<I35*1),"PASS","FAIL")) -> #N/A | N35: =IF(ISBLANK(K35),"CHUADO","")
G36: =G34 -> -82.5 | H36: =H34 | I36: =I34 -> -82.5 | J36: PORT11 | K36: =VLOOKUP($B$34&J36&$F$34,TXRESULT!$A$1:$J$1004,6,FALSE) -> #N/A | M36: =IF(ISBLANK(K36),"",IF(AND(K36*1<I36*1),"PASS","FAIL")) -> #N/A | N36: =IF(ISBLANK(K36),"CHUADO","")
G37: =G34 -> -82.5 | H37: =H34 | I37: =I34 -> -82.5 | J37: PORT12 | K37: =VLOOKUP($B$34&J37&$F$34,TXRESULT!$A$1:$J$1004,6,FALSE) -> #N/A | M37: =IF(ISBLANK(K37),"",IF(AND(K37*1<I37*1),"PASS","FAIL")) -> #N/A | N37: =IF(ISBLANK(K37),"CHUADO","")
G38: =G34 -> -82.5 | H38: =H34 | I38: =I34 -> -82.5 | J38: PORT13 | K38: =VLOOKUP($B$34&J38&$F$34,TXRESULT!$A$1:$J$1004,6,FALSE) -> #N/A | M38: =IF(ISBLANK(K38),"",IF(AND(K38*1<I38*1),"PASS","FAIL")) -> #N/A | N38: =IF(ISBLANK(K38),"CHUADO","")
G39: =G34 -> -82.5 | H39: =H34 | I39: =I34 -> -82.5 | J39: PORT14 | K39: =VLOOKUP($B$34&J39&$F$34,TXRESULT!$A$1:$J$1004,6,FALSE) -> #N/A | M39: =IF(ISBLANK(K39),"",IF(AND(K39*1<I39*1),"PASS","FAIL")) -> #N/A | N39: =IF(ISBLANK(K39),"CHUADO","")
G40: =G34 -> -82.5 | H40: =H34 | I40: =I34 -> -82.5 | J40: PORT15 | K40: =VLOOKUP($B$34&J40&$F$34,TXRESULT!$A$1:$J$1004,6,FALSE) -> #N/A | M40: =IF(ISBLANK(K40),"",IF(AND(K40*1<I40*1),"PASS","FAIL")) -> #N/A | N40: =IF(ISBLANK(K40),"CHUADO","")
...

Sheet CH17-CH24
E1: TỔNG CÔNG TY CÔNG NGHIỆP CÔNG NGHỆ CAO VIETTEL | M1: Mã dự án:
E2: KHỐI 2 - TRUNG TÂM NGHIÊN CỨU THIẾT BỊ VÔ TUYẾN BĂNG RỘNG | M2: Tài liệu HDĐK:
M3: Mã sản phẩm:
E4: PHIẾU ĐO KIỂM | M4: Mã mẫu: | N4: 32T32R
A5: Thông tin về máy đo, dụng cụ đo | E5: VSA: | F5: N9020A | I5: S/N: | L5: Hạn kiểm định: | M5: 2023
E6: VSG: | F6: N5182B | I6: S/N: | J6: MY57300543 | L6: Hạn kiểm định: | M6: 2023
E7: BBU: | F7: SUPERMICRO195 | I7: Type: | J7: Xeon D | L7: FW Version:
E8: RRU: | F8: 32T32R | I8: ID. No.: | J8: ='CH1-CH8'!$J$8 -> 31 | L8: FW Version: | M8: 2.12.10
E9: FREQ (MHz) | F9: 2550 | I9: BW (MHz) | J9: 100 | L9: FPGA Version: | M9: ='CH1-CH8'!M8 -> 3.4.10
A10: Thông tin điều kiện thực hiện | E10: Địa điểm: | F10: Phòng Lab EnodeB, tầng 13, Tòa nhà Viettel Hòa Lạc
E11: Môi trường: | F11: Phòng LAB | I11: Nhiệt độ: | L11: Độ ẩm:
E12: Thời gian: | F12: Từ: | I12: Đến: | L12: Tổng thời gian:
A13: STT | B13: THAM SỐ ĐO ĐẠC | E13: ĐƠN VỊ | F13: GIÁ TRỊ YÊU CẦU | J13: GIÁ TRỊ ĐO | L13: TIÊU CHUẨN THAM CHIẾU | M13: ĐÁNH GIÁ | N13: GHI CHÚ
F14: NR-TM | G14: SPECS | H14: MIN | I14: MAX
A15: I | B15: Conducted Transmitter Characteristics
A16: 1.1 | B16: Base station output power | E16: dBm | F16: TM1.1 | G16: 40 | H16: 37.3 | I16: 42.7 | J16: PORT17 | K16: =VLOOKUP($B$16&J16&$F$16,TXRESULT!$A$1:$J$1004,6,FALSE) -> 39.8 | L16: TS 38.141 / Chapter 6.2: Base station output power | M16: =IF(ISBLANK(K16),"",IF(AND(K16*1>H16*1,K16*1<I16*1),"PASS","FAIL")) -> PASS | N16: =IF(ISBLANK(K16),"CHUADO","")
G17: 40 | H17: 37.3 | I17: 42.7 | J17: PORT18 | K17: =VLOOKUP($B$16&J17&$F$16,TXRESULT!$A$1:$J$1004,6,FALSE) -> 39.7 | M17: =IF(ISBLANK(K17),"",IF(AND(K17*1>H17*1,K17*1<I17*1),"PASS","FAIL")) -> PASS | N17: =IF(ISBLANK(K17),"CHUADO","")
G18: 40 | H18: 37.3 | I18: 42.7 | J18: PORT19 | K18: =VLOOKUP($B$16&J18&$F$16,TXRESULT!$A$1:$J$1004,6,FALSE) -> 39.8 | M18: =IF(ISBLANK(K18),"",IF(AND(K18*1>H18*1,K18*1<I18*1),"PASS","FAIL")) -> PASS | N18: =IF(ISBLANK(K18),"CHUADO","")
G19: 40 | H19: 37.3 | I19: 42.7 | J19: PORT20 | K19: =VLOOKUP($B$16&J19&$F$16,TXRESULT!$A$1:$J$1004,6,FALSE) -> 39.6 | M19: =IF(ISBLANK(K19),"",IF(AND(K19*1>H19*1,K19*1<I19*1),"PASS","FAIL")) -> PASS | N19: =IF(ISBLANK(K19),"CHUADO","")
G20: 40 | H20: 37.3 | I20: 42.7 | J20: PORT21 | K20: =VLOOKUP($B$16&J20&$F$16,TXRESULT!$A$1:$J$1004,6,FALSE) -> 40 | M20: =IF(ISBLANK(K20),"",IF(AND(K20*1>H20*1,K20*1<I20*1),"PASS","FAIL")) -> PASS | N20: =IF(ISBLANK(K20),"CHUADO","")
G21: 40 | H21: 37.3 | I21: 42.7 | J21: PORT22 | K21: =VLOOKUP($B$16&J21&$F$16,TXRESULT!$A$1:$J$1004,6,FALSE) -> 39.5 | M21: =IF(ISBLANK(K21),"",IF(AND(K21*1>H21*1,K21*1<I21*1),"PASS","FAIL")) -> PASS | N21: =IF(ISBLANK(K21),"CHUADO","")
G22: 40 | H22: 37.3 | I22: 42.7 | J22: PORT23 | K22: =VLOOKUP($B$16&J22&$F$16,TXRESULT!$A$1:$J$1004,6,FALSE) -> 39.7 | M22: =IF(ISBLANK(K22),"",IF(AND(K22*1>H22*1,K22*1<I22*1),"PASS","FAIL")) -> PASS | N22: =IF(ISBLANK(K22),"CHUADO","")
G23: 40 | H23: 37.3 | I23: 42.7 | J23: PORT24 | K23: =VLOOKUP($B$16&J23&$F$16,TXRESULT!$A$1:$J$1004,6,FALSE) -> 39.4 | M23: =IF(ISBLANK(K23),"",IF(AND(K23*1>H23*1,K23*1<I23*1),"PASS","FAIL")) -> PASS | N23: =IF(ISBLANK(K23),"CHUADO","")
B24: Output Power Dynamic | E24: =IF(OR(K24="",AND(H24="",I24="")),"",IF(OR(AND(K24<>"",I24<>"",K24>I24),AND(K24<>"",H24<>"",K24<H24)),"FAIL","PASS"))
A25: 1.2 | B25: Total power dynamic range | E25: dB | F25: TM2.0a TM3.1a | G25: 23.9 | H25: =G25 -> 23.9 | I25: =IF(ISBLANK('[1]CH1-CH8'!G11),"",('[1]CH1-CH8'!G11)) | J25: PORT17 | K25: =VLOOKUP($B$25&J25&$F$25,TXRESULT!$A$1:$J$1004,6,FALSE) -> 26.1 | L25: TS 38.141 / Chapter 6.3.3: Total power dynamic range / 30 kHz SCS | M25: =IF(ISBLANK(K25),"",IF(AND(K25*1>H25*1),"PASS","FAIL")) -> PASS | N25: =IF(ISBLANK(K25),"CHUADO","")
G26: =G25 -> 23.9 | H26: =H25 -> 23.9 | I26: =I25 | J26: PORT18 | K26: =VLOOKUP($B$25&J26&$F$25,TXRESULT!$A$1:$J$1004,6,FALSE) -> 26.2 | M26: =IF(ISBLANK(K26),"",IF(AND(K26*1>H26*1),"PASS","FAIL")) -> PASS | N26: =IF(ISBLANK(K26),"CHUADO","")
G27: =G25 -> 23.9 | H27: =H25 -> 23.9 | I27: =I25 | J27: PORT19 | K27: =VLOOKUP($B$25&J27&$F$25,TXRESULT!$A$1:$J$1004,6,FALSE) -> 26.5 | M27: =IF(ISBLANK(K27),"",IF(AND(K27*1>H27*1),"PASS","FAIL")) -> PASS | N27: =IF(ISBLANK(K27),"CHUADO","")
G28: =G25 -> 23.9 | H28: =H25 -> 23.9 | I28: =I25 | J28: PORT20 | K28: =VLOOKUP($B$25&J28&$F$25,TXRESULT!$A$1:$J$1004,6,FALSE) -> 26 | M28: =IF(ISBLANK(K28),"",IF(AND(K28*1>H28*1),"PASS","FAIL")) -> PASS | N28: =IF(ISBLANK(K28),"CHUADO","")
G29: =G25 -> 23.9 | H29: =H25 -> 23.9 | I29: =I25 | J29: PORT21 | K29: =VLOOKUP($B$25&J29&$F$25,TXRESULT!$A$1:$J$1004,6,FALSE) -> 26.3 | M29: =IF(ISBLANK(K29),"",IF(AND(K29*1>H29*1),"PASS","FAIL")) -> PASS | N29: =IF(ISBLANK(K29),"CHUADO","")
G30: =G25 -> 23.9 | H30: =H25 -> 23.9 | I30: =I25 | J30: PORT22 | K30: =VLOOKUP($B$25&J30&$F$25,TXRESULT!$A$1:$J$1004,6,FALSE) -> 26.9 | M30: =IF(ISBLANK(K30),"",IF(AND(K30*1>H30*1),"PASS","FAIL")) -> PASS | N30: =IF(ISBLANK(K30),"CHUADO","")
G31: =G25 -> 23.9 | H31: =H25 -> 23.9 | I31: =I25 | J31: PORT23 | K31: =VLOOKUP($B$25&J31&$F$25,TXRESULT!$A$1:$J$1004,6,FALSE) -> 25.9 | M31: =IF(ISBLANK(K31),"",IF(AND(K31*1>H31*1),"PASS","FAIL")) -> PASS | N31: =IF(ISBLANK(K31),"CHUADO","")
G32: =G25 -> 23.9 | H32: =H25 -> 23.9 | I32: =I25 | J32: PORT24 | K32: =VLOOKUP($B$25&J32&$F$25,TXRESULT!$A$1:$J$1004,6,FALSE) -> 26.1 | M32: =IF(ISBLANK(K32),"",IF(AND(K32*1>H32*1),"PASS","FAIL")) -> PASS | N32: =IF(ISBLANK(K32),"CHUADO","")
B33: TX Transmittion ON/OFF Power | M33: =IF(ISBLANK(K33),"",IF(AND(K33*1>H33*1),"PASS","FAIL"))
A34: 1.3 | B34: Transmitter OFF power | E34: dBm/ MHz | F34: TM1.1 | G34: -82.5 | H34: =IF(ISBLANK('[1]CH1-CH8'!F17),"",('[1]CH1-CH8'!F17)) | I34: -82.5 | J34: PORT17 | K34: =VLOOKUP($B$34&J34&$F$34,TXRESULT!$A$1:$J$1004,6,FALSE) -> #N/A | L34: TS 38.141 / Chapter 6.4.1: Transmitter OFF power/ 6.4.1.3 | M34: =IF(ISBLANK(K34),"",IF(AND(K34*1<I34*1),"PASS","FAIL")) -> #N/A | N34: =IF(ISBLANK(K34),"CHUADO","")
G35: =G34 -> -82.5 | H35: =H34 | I35: =I34 -> -82.5 | J35: PORT18 | K35: =VLOOKUP($B$34&J35&$F$34,TXRESULT!$A$1:$J$1004,6,FALSE) -> #N/A | M35: =IF(ISBLANK(K35),"",IF(AND(K35*1<I35*1),"PASS","FAIL")) -> #N/A | N35: =IF(ISBLANK(K35),"CHUADO","")
G36: =G34 -> -82.5 | H36: =H34 | I36: =I34 -> -82.5 | J36: PORT19 | K36: =VLOOKUP($B$34&J36&$F$34,TXRESULT!$A$1:$J$1004,6,FALSE) -> #N/A | M36: =IF(ISBLANK(K36),"",IF(AND(K36*1<I36*1),"PASS","FAIL")) -> #N/A | N36: =IF(ISBLANK(K36),"CHUADO","")
G37: =G34 -> -82.5 | H37: =H34 | I37: =I34 -> -82.5 | J37: PORT20 | K37: =VLOOKUP($B$34&J37&$F$34,TXRESULT!$A$1:$J$1004,6,FALSE) -> #N/A | M37: =IF(ISBLANK(K37),"",IF(AND(K37*1<I37*1),"PASS","FAIL")) -> #N/A | N37: =IF(ISBLANK(K37),"CHUADO","")
G38: =G34 -> -82.5 | H38: =H34 | I38: =I34 -> -82.5 | J38: PORT21 | K38: =VLOOKUP($B$34&J38&$F$34,TXRESULT!$A$1:$J$1004,6,FALSE) -> #N/A | M38: =IF(ISBLANK(K38),"",IF(AND(K38*1<I38*1),"PASS","FAIL")) -> #N/A | N38: =IF(ISBLANK(K38),"CHUADO","")
G39: =G34 -> -82.5 | H39: =H34 | I39: =I34 -> -82.5 | J39: PORT22 | K39: =VLOOKUP($B$34&J39&$F$34,TXRESULT!$A$1:$J$1004,6,FALSE) -> #N/A | M39: =IF(ISBLANK(K39),"",IF(AND(K39*1<I39*1),"PASS","FAIL")) -> #N/A | N39: =IF(ISBLANK(K39),"CHUADO","")
G40: =G34 -> -82.5 | H40: =H34 | I40: =I34 -> -82.5 | J40: PORT23 | K40: =VLOOKUP($B$34&J40&$F$34,TXRESULT!$A$1:$J$1004,6,FALSE) -> #N/A | M40: =IF(ISBLANK(K40),"",IF(AND(K40*1<I40*1),"PASS","FAIL")) -> #N/A | N40: =IF(ISBLANK(K40),"CHUADO","")
...

Sheet CH25-CH32
E1: TỔNG CÔNG TY CÔNG NGHIỆP CÔNG NGHỆ CAO VIETTEL | M1: Mã dự án:
E2: KHỐI 2 - TRUNG TÂM NGHIÊN CỨU THIẾT BỊ VÔ TUYẾN BĂNG RỘNG | M2: Tài liệu HDĐK:
M3: Mã sản phẩm:
E4: PHIẾU ĐO KIỂM | M4: Mã mẫu: | N4: 32T32R
A5: Thông tin về máy đo, dụng cụ đo | E5: VSA: | F5: N9020A | I5: S/N: | L5: Hạn kiểm định: | M5: 2023
E6: VSG: | F6: N5182B | I6: S/N: | J6: MY57300543 | L6: Hạn kiểm định: | M6: 2023
E7: BBU: | F7: SUPERMICRO195 | I7: Type: | J7: Xeon D | L7: FW Version:
E8: RRU: | F8: 32T32R | I8: ID. No.: | J8: ='CH1-CH8'!$J$8 -> 31 | L8: FW Version: | M8: ='CH1-CH8'!M8 -> 3.4.10
E9: FREQ (MHz) | F9: 2550 | I9: BW (MHz) | J9: 100 | L9: FPGA Version:
A10: Thông tin điều kiện thực hiện | E10: Địa điểm: | F10: Phòng Lab EnodeB, tầng 13, Tòa nhà Viettel Hòa Lạc
E11: Môi trường: | F11: Phòng LAB | I11: Nhiệt độ: | L11: Độ ẩm:
E12: Thời gian: | F12: Từ: | I12: Đến: | L12: Tổng thời gian:
A13: STT | B13: THAM SỐ ĐO ĐẠC | E13: ĐƠN VỊ | F13: GIÁ TRỊ YÊU CẦU | J13: GIÁ TRỊ ĐO | L13: TIÊU CHUẨN THAM CHIẾU | M13: ĐÁNH GIÁ | N13: GHI CHÚ
F14: NR-TM | G14: SPECS | H14: MIN | I14: MAX
A15: I | B15: Conducted Transmitter Characteristics
A16: 1.1 | B16: Base station output power | E16: dBm | F16: TM1.1 | G16: 40 | H16: 37.3 | I16: 42.7 | J16: PORT25 | K16: =VLOOKUP($B$16&J16&$F$16,TXRESULT!$A$1:$J$1004,6,FALSE) -> 39.8 | L16: TS 38.141 / Chapter 6.2: Base station output power | M16: =IF(ISBLANK(K16),"",IF(AND(K16*1>H16*1,K16*1<I16*1),"PASS","FAIL")) -> PASS | N16: =IF(ISBLANK(K16),"CHUADO","")
G17: 40 | H17: 37.3 | I17: 42.7 | J17: PORT26 | K17: =VLOOKUP($B$16&J17&$F$16,TXRESULT!$A$1:$J$1004,6,FALSE) -> 39.7 | M17: =IF(ISBLANK(K17),"",IF(AND(K17*1>H17*1,K17*1<I17*1),"PASS","FAIL")) -> PASS | N17: =IF(ISBLANK(K17),"CHUADO","")
G18: 40 | H18: 37.3 | I18: 42.7 | J18: PORT27 | K18: =VLOOKUP($B$16&J18&$F$16,TXRESULT!$A$1:$J$1004,6,FALSE) -> 39.7 | M18: =IF(ISBLANK(K18),"",IF(AND(K18*1>H18*1,K18*1<I18*1),"PASS","FAIL")) -> PASS | N18: =IF(ISBLANK(K18),"CHUADO","")
G19: 40 | H19: 37.3 | I19: 42.7 | J19: PORT28 | K19: =VLOOKUP($B$16&J19&$F$16,TXRESULT!$A$1:$J$1004,6,FALSE) -> 39.6 | M19: =IF(ISBLANK(K19),"",IF(AND(K19*1>H19*1,K19*1<I19*1),"PASS","FAIL")) -> PASS | N19: =IF(ISBLANK(K19),"CHUADO","")
G20: 40 | H20: 37.3 | I20: 42.7 | J20: PORT29 | K20: =VLOOKUP($B$16&J20&$F$16,TXRESULT!$A$1:$J$1004,6,FALSE) -> 39.9 | M20: =IF(ISBLANK(K20),"",IF(AND(K20*1>H20*1,K20*1<I20*1),"PASS","FAIL")) -> PASS | N20: =IF(ISBLANK(K20),"CHUADO","")
G21: 40 | H21: 37.3 | I21: 42.7 | J21: PORT30 | K21: =VLOOKUP($B$16&J21&$F$16,TXRESULT!$A$1:$J$1004,6,FALSE) -> 39.8 | M21: =IF(ISBLANK(K21),"",IF(AND(K21*1>H21*1,K21*1<I21*1),"PASS","FAIL")) -> PASS | N21: =IF(ISBLANK(K21),"CHUADO","")
G22: 40 | H22: 37.3 | I22: 42.7 | J22: PORT31 | K22: =VLOOKUP($B$16&J22&$F$16,TXRESULT!$A$1:$J$1004,6,FALSE) -> 39.6 | M22: =IF(ISBLANK(K22),"",IF(AND(K22*1>H22*1,K22*1<I22*1),"PASS","FAIL")) -> PASS | N22: =IF(ISBLANK(K22),"CHUADO","")
G23: 40 | H23: 37.3 | I23: 42.7 | J23: PORT32 | K23: =VLOOKUP($B$16&J23&$F$16,TXRESULT!$A$1:$J$1004,6,FALSE) -> 39.4 | M23: =IF(ISBLANK(K23),"",IF(AND(K23*1>H23*1,K23*1<I23*1),"PASS","FAIL")) -> PASS | N23: =IF(ISBLANK(K23),"CHUADO","")
B24: Output Power Dynamic | E24: =IF(OR(K24="",AND(H24="",I24="")),"",IF(OR(AND(K24<>"",I24<>"",K24>I24),AND(K24<>"",H24<>"",K24<H24)),"FAIL","PASS"))
A25: 1.2 | B25: Total power dynamic range | E25: dB | F25: TM2.0a TM3.1a | G25: 23.9 | H25: =G25 -> 23.9 | I25: =IF(ISBLANK('[1]CH1-CH8'!G11),"",('[1]CH1-CH8'!G11)) | J25: PORT25 | K25: =VLOOKUP($B$25&J25&$F$25,TXRESULT!$A$1:$J$1004,6,FALSE) -> 26.2 | L25: TS 38.141 / Chapter 6.3.3: Total power dynamic range / 30 kHz SCS | M25: =IF(ISBLANK(K25),"",IF(AND(K25*1>H25*1),"PASS","FAIL")) -> PASS | N25: =IF(ISBLANK(K25),"CHUADO","")
G26: =G25 -> 23.9 | H26: =H25 -> 23.9 | I26: =I25 | J26: PORT26 | K26: =VLOOKUP($B$25&J26&$F$25,TXRESULT!$A$1:$J$1004,6,FALSE) -> 26 | M26: =IF(ISBLANK(K26),"",IF(AND(K26*1>H26*1),"PASS","FAIL")) -> PASS | N26: =IF(ISBLANK(K26),"CHUADO","")
G27: =G25 -> 23.9 | H27: =H25 -> 23.9 | I27: =I25 | J27: PORT27 | K27: =VLOOKUP($B$25&J27&$F$25,TXRESULT!$A$1:$J$1004,6,FALSE) -> 26.2 | M27: =IF(ISBLANK(K27),"",IF(AND(K27*1>H27*1),"PASS","FAIL")) -> PASS | N27: =IF(ISBLANK(K27),"CHUADO","")
G28: =G25 -> 23.9 | H28: =H25 -> 23.9 | I28: =I25 | J28: PORT28 | K28: =VLOOKUP($B$25&J28&$F$25,TXRESULT!$A$1:$J$1004,6,FALSE) -> 26.4 | M28: =IF(ISBLANK(K28),"",IF(AND(K28*1>H28*1),"PASS","FAIL")) -> PASS | N28: =IF(ISBLANK(K28),"CHUADO","")
G29: =G25 -> 23.9 | H29: =H25 -> 23.9 | I29: =I25 | J29: PORT29 | K29: =VLOOKUP($B$25&J29&$F$25,TXRESULT!$A$1:$J$1004,6,FALSE) -> 26 | M29: =IF(ISBLANK(K29),"",IF(AND(K29*1>H29*1),"PASS","FAIL")) -> PASS | N29: =IF(ISBLANK(K29),"CHUADO","")
G30: =G25 -> 23.9 | H30: =H25 -> 23.9 | I30: =I25 | J30: PORT30 | K30: =VLOOKUP($B$25&J30&$F$25,TXRESULT!$A$1:$J$1004,6,FALSE) -> 25.8 | M30: =IF(ISBLANK(K30),"",IF(AND(K30*1>H30*1),"PASS","FAIL")) -> PASS | N30: =IF(ISBLANK(K30),"CHUADO","")
G31: =G25 -> 23.9 | H31: =H25 -> 23.9 | I31: =I25 | J31: PORT31 | K31: =VLOOKUP($B$25&J31&$F$25,TXRESULT!$A$1:$J$1004,6,FALSE) -> 26 | M31: =IF(ISBLANK(K31),"",IF(AND(K31*1>H31*1),"PASS","FAIL")) -> PASS | N31: =IF(ISBLANK(K31),"CHUADO","")
G32: =G25 -> 23.9 | H32: =H25 -> 23.9 | I32: =I25 | J32: PORT32 | K32: =VLOOKUP($B$25&J32&$F$25,TXRESULT!$A$1:$J$1004,6,FALSE) -> 26 | M32: =IF(ISBLANK(K32),"",IF(AND(K32*1>H32*1),"PASS","FAIL")) -> PASS | N32: =IF(ISBLANK(K32),"CHUADO","")
B33: TX Transmittion ON/OFF Power | M33: =IF(ISBLANK(K33),"",IF(AND(K33*1>H33*1),"PASS","FAIL"))
A34: 1.3 | B34: Transmitter OFF power | E34: dBm/ MHz | F34: TM1.1 | G34: -82.5 | H34: =IF(ISBLANK('[1]CH1-CH8'!F17),"",('[1]CH1-CH8'!F17)) | I34: -82.5 | J34: PORT25 | K34: =VLOOKUP($B$34&J34&$F$34,TXRESULT!$A$1:$J$1004,6,FALSE) -> #N/A | L34: TS 38.141 / Chapter 6.4.1: Transmitter OFF power/ 6.4.1.3 | M34: =IF(ISBLANK(K34),"",IF(AND(K34*1<I34*1),"PASS","FAIL")) -> #N/A | N34: =IF(ISBLANK(K34),"CHUADO","")
G35: =G34 -> -82.5 | H35: =H34 | I35: =I34 -> -82.5 | J35: PORT26 | K35: =VLOOKUP($B$34&J35&$F$34,TXRESULT!$A$1:$J$1004,6,FALSE) -> #N/A | M35: =IF(ISBLANK(K35),"",IF(AND(K35*1<I35*1),"PASS","FAIL")) -> #N/A | N35: =IF(ISBLANK(K35),"CHUADO","")
G36: =G34 -> -82.5 | H36: =H34 | I36: =I34 -> -82.5 | J36: PORT27 | K36: =VLOOKUP($B$34&J36&$F$34,TXRESULT!$A$1:$J$1004,6,FALSE) -> #N/A | M36: =IF(ISBLANK(K36),"",IF(AND(K36*1<I36*1),"PASS","FAIL")) -> #N/A | N36: =IF(ISBLANK(K36),"CHUADO","")
G37: =G34 -> -82.5 | H37: =H34 | I37: =I34 -> -82.5 | J37: PORT28 | K37: =VLOOKUP($B$34&J37&$F$34,TXRESULT!$A$1:$J$1004,6,FALSE) -> #N/A | M37: =IF(ISBLANK(K37),"",IF(AND(K37*1<I37*1),"PASS","FAIL")) -> #N/A | N37: =IF(ISBLANK(K37),"CHUADO","")
G38: =G34 -> -82.5 | H38: =H34 | I38: =I34 -> -82.5 | J38: PORT29 | K38: =VLOOKUP($B$34&J38&$F$34,TXRESULT!$A$1:$J$1004,6,FALSE) -> #N/A | M38: =IF(ISBLANK(K38),"",IF(AND(K38*1<I38*1),"PASS","FAIL")) -> #N/A | N38: =IF(ISBLANK(K38),"CHUADO","")
G39: =G34 -> -82.5 | H39: =H34 | I39: =I34 -> -82.5 | J39: PORT30 | K39: =VLOOKUP($B$34&J39&$F$34,TXRESULT!$A$1:$J$1004,6,FALSE) -> #N/A | M39: =IF(ISBLANK(K39),"",IF(AND(K39*1<I39*1),"PASS","FAIL")) -> #N/A | N39: =IF(ISBLANK(K39),"CHUADO","")
G40: =G34 -> -82.5 | H40: =H34 | I40: =I34 -> -82.5 | J40: PORT31 | K40: =VLOOKUP($B$34&J40&$F$34,TXRESULT!$A$1:$J$1004,6,FALSE) -> #N/A | M40: =IF(ISBLANK(K40),"",IF(AND(K40*1<I40*1),"PASS","FAIL")) -> #N/A | N40: =IF(ISBLANK(K40),"CHUADO","")
...

Sheet TXRESULT
B1: PORT | C1: CLAUSE | D1: SPEC | E1: MIN | F1: MEAS | G1: MAX | H1: NRTM | I1: Time | J1: PASS/FAIL | K1: NOTE | P1: Yeu cau voi file report ket qua
A2: =C2&B2&H2 -> Base station output powerPORT1TM1.1 | B2: PORT1 | C2: Base station output power | D2: 40 | E2: 37.3 | F2: 40.1 | G2: 42.7 | H2: TM1.1 | I2: 0.24914352 | J2: PASS | P2: - Xoa bo dau + trong truong CLAUSE
A3: =C3&B3&H3 -> Base station output powerPORT2TM1.1 | B3: PORT2 | C3: Base station output power | D3: 40 | E3: 37.3 | F3: 40.3 | G3: 42.7 | H3: TM1.1 | I3: 0.24935185 | J3: PASS | P3: - Doi ten TM1.1 thanh TM1.1 tuong ung voi cac TM con laij
A4: =C4&B4&H4 -> Base station output powerPORT3TM1.1 | B4: PORT3 | C4: Base station output power | D4: 40 | E4: 37.3 | F4: 40.1 | G4: 42.7 | H4: TM1.1 | I4: 0.24956019 | J4: PASS | P4: - Ten trong CLAUSE khong them truong NRTM
A5: =C5&B5&H5 -> Base station output powerPORT4TM1.1 | B5: PORT4 | C5: Base station output power | D5: 40 | E5: 37.3 | F5: 40.1 | G5: 42.7 | H5: TM1.1 | I5: 0.24976852 | J5: PASS | P5: - Voi bai do OBUE, SPUR them truong thong tin OBUE1,OBUE2,OBUE3,OBUE4 va SPUR1,SPUR2,SPUR3,SPUR4,SPUR5
A6: =C6&B6&H6 -> Base station output powerPORT5TM1.1 | B6: PORT5 | C6: Base station output power | D6: 40 | E6: 37.3 | F6: 39.6 | G6: 42.7 | H6: TM1.1 | I6: 0.24996528 | J6: PASS | P6: - Voi bai do IMD them truong thong tin nhu OBUE va SPUR
A7: =C7&B7&H7 -> Base station output powerPORT6TM1.1 | B7: PORT6 | C7: Base station output power | D7: 40 | E7: 37.3 | F7: 39.9 | G7: 42.7 | H7: TM1.1 | I7: 0.25017361 | J7: PASS | P7: - Voi bai do IMD, ghi truong IMD Ad…, IMD Oper…, IMD Spur…
A8: =C8&B8&H8 -> Base station output powerPORT7TM1.1 | B8: PORT7 | C8: Base station output power | D8: 40 | E8: 37.3 | F8: 39.9 | G8: 42.7 | H8: TM1.1 | I8: 0.25038194 | J8: PASS
A9: =C9&B9&H9 -> Base station output powerPORT8TM1.1 | B9: PORT8 | C9: Base station output power | D9: 40 | E9: 37.3 | F9: 39.8 | G9: 42.7 | H9: TM1.1 | I9: 0.25059028 | J9: PASS | Q9: NRTM | R9: PORT | S9: MEAS
A10: =C10&B10&H10 -> Base station output powerPORT9TM1.1 | B10: PORT9 | C10: Base station output power | D10: 40 | E10: 37.3 | F10: 39.8 | G10: 42.7 | H10: TM1.1 | I10: 0.25078704 | J10: PASS | P10: Base station output power | Q10: TM1.1 | R10: PORT16 | S10: =VLOOKUP(P10&R10,A1:$J$613,6,FALSE) -> #N/A | U10: 32
A11: =C11&B11&H11 -> Base station output powerPORT10TM1.1 | B11: PORT10 | C11: Base station output power | D11: 40 | E11: 37.3 | F11: 39.5 | G11: 42.7 | H11: TM1.1 | I11: 0.25099537 | J11: PASS | P11: Occupied bandwidth | Q11: TM1.1 | R11: PORT21 | S11: =VLOOKUP(P11&R11,A2:$J$613,6,FALSE) -> #N/A | U11: 32
A12: =C12&B12&H12 -> Base station output powerPORT11TM1.1 | B12: PORT11 | C12: Base station output power | D12: 40 | E12: 37.3 | F12: 39.8 | G12: 42.7 | H12: TM1.1 | I12: 0.2512037 | J12: PASS | P12: Adjacent channel leakage power | Q12: TM1.1 TM1.2 | R12: PORT3 | S12: =MIN(IF((B2:B97=R12)*(C2:C97=P12),F2:F97,"")) -> #VALUE! | U12: 64
A13: =C13&B13&H13 -> Base station output powerPORT12TM1.1 | B13: PORT12 | C13: Base station output power | D13: 40 | E13: 37.3 | F13: 39.6 | G13: 42.7 | H13: TM1.1 | I13: 0.25141204 | J13: PASS | P13: Operating band Unwanted emissions | Q13: TM1.1 TM1.2 | R13: PORT1 | S13: {=MAX(IF((B1:B1000=R13)*(C1:C1000=P13)*(K1:K1000="OBUE1"),F1:F1000,""))} -> 0 | U13: =3*32*2 -> 192
A14: =C14&B14&H14 -> Base station output powerPORT13TM1.1 | B14: PORT13 | C14: Base station output power | D14: 40 | E14: 37.3 | F14: 39.5 | G14: 42.7 | H14: TM1.1 | I14: 0.25162037 | J14: PASS | P14: Modulation quality | Q14: TM3.1a | R14: PORT5 | S14: =VLOOKUP(P14&R14,A5:$J$613,6,FALSE) -> #N/A | U14: =32*6 -> 192
A15: =C15&B15&H15 -> Base station output powerPORT14TM1.1 | B15: PORT14 | C15: Base station output power | D15: 40 | E15: 37.3 | F15: 39.8 | G15: 42.7 | H15: TM1.1 | I15: 0.2518287 | J15: PASS | P15: Frequency error | Q15: TM2.0 TM2.0a TM3.1 TM3.1a | R15: PORT6 | S15: {=MAX(IF((B1:B613=R15)*(C1:C613=P15),F1:F613,""))} -> 0 | U15: =32*6 -> 192
A16: =C16&B16&H16 -> Base station output powerPORT15TM1.1 | B16: PORT15 | C16: Base station output power | D16: 40 | E16: 37.3 | F16: 39.8 | G16: 42.7 | H16: TM1.1 | I16: 0.25202546 | J16: PASS | P16: Total power dynamic range | Q16: TM2.0a TM3.1a | R16: PORT7 | S16: =VLOOKUP(P16&R16,A7:$J$613,6,FALSE) -> #N/A | U16: 32
A17: =C17&B17&H17 -> Base station output powerPORT16TM1.1 | B17: PORT16 | C17: Base station output power | D17: 40 | E17: 37.3 | F17: 39.9 | G17: 42.7 | H17: TM1.1 | I17: 0.2522338 | J17: PASS | P17: Transmitter spurious emission | Q17: TM1.1 | R17: PORT1 | S17: {=MIN(IF((C1:C2000=P17)*(B1:B2000=R17)*(K1:K2000="SPUR1"),F1:F2000,""))} -> 0 | U17: =32*5 -> 160
A18: =C18&B18&H18 -> Base station output powerPORT17TM1.1 | B18: PORT17 | C18: Base station output power | D18: 40 | E18: 37.3 | F18: 39.8 | G18: 42.7 | H18: TM1.1 | I18: 0.25244213 | J18: PASS | P18: Transmitter OFF power | U18: 32
A19: =C19&B19&H19 -> Base station output powerPORT18TM1.1 | B19: PORT18 | C19: Base station output power | D19: 40 | E19: 37.3 | F19: 39.7 | G19: 42.7 | H19: TM1.1 | I19: 0.25265046 | J19: PASS | P19: Transmitter transient period | U19: 32
A20: =C20&B20&H20 -> Base station output powerPORT19TM1.1 | B20: PORT19 | C20: Base station output power | D20: 40 | E20: 37.3 | F20: 39.8 | G20: 42.7 | H20: TM1.1 | I20: 0.25284722 | J20: PASS | P20: Time alignment error | U20: 32
A21: =C21&B21&H21 -> Base station output powerPORT20TM1.1 | B21: PORT20 | C21: Base station output power | D21: 40 | E21: 37.3 | F21: 39.6 | G21: 42.7 | H21: TM1.1 | I21: 0.25305556 | J21: PASS | P21: IMD Adjacent channel leakage power | U21: 32
A22: =C22&B22&H22 -> Base station output powerPORT21TM1.1 | B22: PORT21 | C22: Base station output power | D22: 40 | E22: 37.3 | F22: 40 | G22: 42.7 | H22: TM1.1 | I22: 0.25326389 | J22: PASS | P22: IMD Operating band Unwanted emissions | U22: =3*32*1 -> 96
A23: =C23&B23&H23 -> Base station output powerPORT22TM1.1 | B23: PORT22 | C23: Base station output power | D23: 40 | E23: 37.3 | F23: 39.5 | G23: 42.7 | H23: TM1.1 | I23: 0.25347222 | J23: PASS | P23: IMD Transmitter spurious emission | U23: =32*5 -> 160
A24: =C24&B24&H24 -> Base station output powerPORT23TM1.1 | B24: PORT23 | C24: Base station output power | D24: 40 | E24: 37.3 | F24: 39.7 | G24: 42.7 | H24: TM1.1 | I24: 0.25368056 | J24: PASS | U24: =SUM(U10:U23) -> 1280
A25: =C25&B25&H25 -> Base station output powerPORT24TM1.1 | B25: PORT24 | C25: Base station output power | D25: 40 | E25: 37.3 | F25: 39.4 | G25: 42.7 | H25: TM1.1 | I25: 0.25388889 | J25: PASS
A26: =C26&B26&H26 -> Base station output powerPORT25TM1.1 | B26: PORT25 | C26: Base station output power | D26: 40 | E26: 37.3 | F26: 39.8 | G26: 42.7 | H26: TM1.1 | I26: 0.25408565 | J26: PASS
A27: =C27&B27&H27 -> Base station output powerPORT26TM1.1 | B27: PORT26 | C27: Base station output power | D27: 40 | E27: 37.3 | F27: 39.7 | G27: 42.7 | H27: TM1.1 | I27: 0.25429398 | J27: PASS
A28: =C28&B28&H28 -> Base station output powerPORT27TM1.1 | B28: PORT27 | C28: Base station output power | D28: 40 | E28: 37.3 | F28: 39.7 | G28: 42.7 | H28: TM1.1 | I28: 0.25450231 | J28: PASS
A29: =C29&B29&H29 -> Base station output powerPORT28TM1.1 | B29: PORT28 | C29: Base station output power | D29: 40 | E29: 37.3 | F29: 39.6 | G29: 42.7 | H29: TM1.1 | I29: 0.25469907 | J29: PASS
A30: =C30&B30&H30 -> Base station output powerPORT29TM1.1 | B30: PORT29 | C30: Base station output power | D30: 40 | E30: 37.3 | F30: 39.9 | G30: 42.7 | H30: TM1.1 | I30: 0.25490741 | J30: PASS
A31: =C31&B31&H31 -> Base station output powerPORT30TM1.1 | B31: PORT30 | C31: Base station output power | D31: 40 | E31: 37.3 | F31: 39.8 | G31: 42.7 | H31: TM1.1 | I31: 0.25511574 | J31: PASS
A32: =C32&B32&H32 -> Base station output powerPORT31TM1.1 | B32: PORT31 | C32: Base station output power | D32: 40 | E32: 37.3 | F32: 39.6 | G32: 42.7 | H32: TM1.1 | I32: 0.25532407 | J32: PASS
A33: =C33&B33&H33 -> Base station output powerPORT32TM1.1 | B33: PORT32 | C33: Base station output power | D33: 40 | E33: 37.3 | F33: 39.4 | G33: 42.7 | H33: TM1.1 | I33: 0.25553241 | J33: PASS
A34: =C34&B34&H34 -> Occupied bandwidthPORT1TM1.1 | B34: PORT1 | C34: Occupied bandwidth | D34: 98.28 | G34: 98.28 | H34: TM1.1 | I34: 0.43822917 | J34: PASS
A35: =C35&B35&H35 -> Occupied bandwidthPORT2TM1.1 | B35: PORT2 | C35: Occupied bandwidth | D35: 98.28 | G35: 98.28 | H35: TM1.1 | I35: 0.43850694 | J35: PASS
A36: =C36&B36&H36 -> Occupied bandwidthPORT3TM1.1 | B36: PORT3 | C36: Occupied bandwidth | D36: 98.28 | G36: 98.28 | H36: TM1.1 | I36: 0.43878472 | J36: PASS
A37: =C37&B37&H37 -> Occupied bandwidthPORT4TM1.1 | B37: PORT4 | C37: Occupied bandwidth | D37: 98.28 | G37: 98.28 | H37: TM1.1 | I37: 0.43905093 | J37: PASS
A38: =C38&B38&H38 -> Occupied bandwidthPORT5TM1.1 | B38: PORT5 | C38: Occupied bandwidth | D38: 98.28 | G38: 98.28 | H38: TM1.1 | I38: 0.4393287 | J38: PASS
A39: =C39&B39&H39 -> Occupied bandwidthPORT6TM1.1 | B39: PORT6 | C39: Occupied bandwidth | D39: 98.28 | G39: 98.28 | H39: TM1.1 | I39: 0.43960648 | J39: PASS
A40: =C40&B40&H40 -> Occupied bandwidthPORT7TM1.1 | B40: PORT7 | C40: Occupied bandwidth | D40: 98.28 | G40: 98.28 | H40: TM1.1 | I40: 0.43988426 | J40: PASS
...

Sheet RXRESULT
B1: PORT | C1: CLAUSE | D1: SPEC | E1: MIN | F1: MEAS | G1: MAX | H1: ThoughPut | I1: Time | J1: PASS/FAIL
A2: =C2&B2 -> Reference sensitivity levelPORT1 | B2: PORT1 | C2: Reference sensitivity level | D2: -94.9 | F2: -95 | G2: -94.9 | H2: 98.9 | I2: 0.41263889 | J2: PASS
A3: =C3&B3 -> Reference sensitivity levelPORT2 | B3: PORT2 | C3: Reference sensitivity level | D3: -94.9 | F3: -95 | G3: -94.9 | H3: 99.8 | I3: 0.41311343 | J3: PASS
A4: =C4&B4 -> Reference sensitivity levelPORT3 | B4: PORT3 | C4: Reference sensitivity level | D4: -94.9 | F4: -95 | G4: -94.9 | H4: 99.8 | I4: 0.41357639 | J4: PASS
A5: =C5&B5 -> Reference sensitivity levelPORT4 | B5: PORT4 | C5: Reference sensitivity level | D5: -94.9 | F5: -95 | G5: -94.9 | H5: 99.8 | I5: 0.41405093 | J5: PASS
A6: =C6&B6 -> Reference sensitivity levelPORT5 | B6: PORT5 | C6: Reference sensitivity level | D6: -94.9 | F6: -95 | G6: -94.9 | H6: 99.8 | I6: 0.41452546 | J6: PASS
A7: =C7&B7 -> Reference sensitivity levelPORT6 | B7: PORT6 | C7: Reference sensitivity level | D7: -94.9 | F7: -95 | G7: -94.9 | H7: 99.8 | I7: 0.415 | J7: PASS
A8: =C8&B8 -> Reference sensitivity levelPORT7 | B8: PORT7 | C8: Reference sensitivity level | D8: -94.9 | F8: -95 | G8: -94.9 | H8: 99.8 | I8: 0.41547454 | J8: PASS
A9: =C9&B9 -> Reference sensitivity levelPORT8 | B9: PORT8 | C9: Reference sensitivity level | D9: -94.9 | F9: -95 | G9: -94.9 | H9: 99.8 | I9: 0.41594907 | J9: PASS
A10: =C10&B10 -> Reference sensitivity levelPORT9 | B10: PORT9 | C10: Reference sensitivity level | D10: -94.9 | F10: -95 | G10: -94.9 | H10: 98.9 | I10: 0.41638889 | J10: PASS
A11: =C11&B11 -> Reference sensitivity levelPORT10 | B11: PORT10 | C11: Reference sensitivity level | D11: -94.9 | F11: -95 | G11: -94.9 | H11: 99.8 | I11: 0.41686343 | J11: PASS
A12: =C12&B12 -> Reference sensitivity levelPORT11 | B12: PORT11 | C12: Reference sensitivity level | D12: -94.9 | F12: -95 | G12: -94.9 | H12: 99.8 | I12: 0.41733796 | J12: PASS
A13: =C13&B13 -> Reference sensitivity levelPORT12 | B13: PORT12 | C13: Reference sensitivity level | D13: -94.9 | F13: -95 | G13: -94.9 | H13: 99.8 | I13: 0.4178125 | J13: PASS
... A33: =C33&B33 -> Reference sensitivity levelPORT32 | B33: PORT32 | C33: Reference sensitivity level | D33: -94.9 | F33: -95 | G33: -94.9 | H33: 99.8 | I33: 0.42990741 | J33: PASS
A34: =C34&B34 -> Dynamic rangePORT1 | B34: PORT1 | C34: Dynamic range | D34: -69.1 | F34: -67.1 | H34: 98.9
A35: =C35&B35 -> Dynamic rangePORT2 | B35: PORT2 | C35: Dynamic range | D35: -69.1 | F35: -67.1 | H35: 99.8
A36: =C36&B36 -> Dynamic rangePORT3 | B36: PORT3 | C36: Dynamic range | D36: -69.1 | F36: -67.1 | H36: 99.8
A37: =C37&B37 -> Dynamic rangePORT4 | B37: PORT4 | C37: Dynamic range | D37: -69.1 | F37: -67.1 | H37: 99.8
A38: =C38&B38 -> Dynamic rangePORT5 | B38: PORT5 | C38: Dynamic range | D38: -69.1 | F38: -67.1 | H38: 99.8
A39: =C39&B39 -> Dynamic rangePORT6 | B39: PORT6 | C39: Dynamic range | D39: -69.1 | F39: -67.1 | H39: 99.8
A40: =C40&B40 -> Dynamic rangePORT7 | B40: PORT7 | C40: Dynamic range | D40: -69.1 | F40: -67.1 | H40: 99.8
A41: =C41&B41 -> Dynamic rangePORT8 | B41: PORT8 | C41: Dynamic range | D41: -69.1 | F41: -67.1 | H41: 99.8
A42: =C42&B42 -> Dynamic rangePORT9 | B42: PORT9 | C42: Dynamic range | D42: -69.1 | F42: -67.1 | H42: 98.9
A43: =C43&B43 -> Dynamic rangePORT10 | B43: PORT10 | C43: Dynamic range | D43: -69.1 | F43: -67.1 | H43: 99.8
A44: =C44&B44 -> Dynamic rangePORT11 | B44: PORT11 | C44: Dynamic range | D44: -69.1 | F44: -67.1 | H44: 99.8
A45: =C45&B45 -> Dynamic rangePORT12 | B45: PORT12 | C45: Dynamic range | D45: -69.1 | F45: -67.1 | H45: 99.8
... A289: =C289&B289 -> In-channel selectivityPORT32 | B289: PORT32 | C289: In-channel selectivity | D289: -71.4 | F289: -55.4 | H289: 99.8

Sheet Conclutsion
A2: Requirements | C2: Test Model | D2: Unit | E2: SPECS | F2: TS38.104 Test requirements | G2: TS38.141-1 Test requirements | H2: QCVN128 Test requirements | I2: MIN | J2: MAX | K2: PASS FAIL | L2: NOTE
A3: Base station Type | E3: 1-H
A4: Base station Class | E4: Wide Area
A5: Frequency | D5: MHz | E5: 2550
A6: Bandwidth | D6: MHz | E6: 100
A7: Base station output power | C7: TM1.1 | D7: dBm | E7: 40 | F7: In normal conditions, Pmax,c,TABC shall remain within +2 dB and -2 dB of the rated carrier output power Prated,c,TABC for each TAB connector as declared by the manufacturer. In extreme conditions, Pmax,c,TABC shall remain within +2.5 dB and -2.5 dB of the rated carrier output power Prated,c,TABC for each TAB connector as declared by the manufacturer. | G7: TS 38141.1 Chapter 6.2 Table 6.2.5-1: Test requirement for conducted BS output power Normal conditions: 3.0 GHz < f ≤ 6.0 GHz: ± 3.0 dB Extreme conditions: 3.0 GHz < f ≤ 6.0 GHz: ± 3.5 dB (NR TM: TM1.1) | I7: =MIN('[2]CH1-CH8'!K16:K23,'[2]CH9-CH16'!K16:K23,'[2]CH17-CH24'!K16:K23,'[2]CH25-CH32'!K16:K23) -> 39.6 | J7: =MAX('[2]CH1-CH8'!K16:K23,'[2]CH9-CH16'!K16:K23,'[2]CH17-CH24'!K16:K23,'[2]CH25-CH32'!K16:K23) -> 41.1
A8: Total power dynamic range | C8: TM2.0a TM3.1a | D8: dB | E8: 23.9 | F8: 6.3.3.2 Minimum requirement for BS type 1-C and BS type 1-H 100MHz/30 kHz SCS: Total power dynamic range ≥ 24.3 dB | G8: Table 6.3.3.5-1: BS total power dynamic range 100MHz/30 kHz SCS: Total power dynamic range ≥ 23.9 dB (NR TM: TM2.0a TM3.1a)
A9: Transmitter OFF power | C9: TM1.1 | D9: dBm | E9: -82.5
A10: Transmitter transient period | C10: TM1.1 | D10: us | E10: 10
A11: Frequency error | C11: TM2.0 TM2.0a TM3.1 TM3.1a | D11: Hz | E11: 139.5 | F11: ±0.05 ppm | G11: ±(0.05 ppm + 12 Hz) | H11: ±0.05 ppm
A12: Modulation quality | B12: QPSK | C12: TM3.3 | D12: % | E12: 18.5 | F12: 0.175 | G12: 0.185 | H12: 0.175
B13: 16 QAM | C13: TM3.2 | D13: % | E13: 13.5 | F13: 0.125 | G13: 0.135 | H13: 0.125
B14: 64 QAM | C14: TM3.1 | D14: % | E14: 9 | F14: 0.08 | G14: 0.09 | H14: 0.08
B15: 256 QAM | C15: TM3.1a | D15: % | E15: 4.5 | F15: 0.035 | G15: 0.045 | H15: 0.035
A16: Time alignment error | C16: TM1.1 | D16: ns | E16: 90 | F16: For MIMO transmission, at each carrier frequency, TAE shall not exceed 65 ns. | G16: For MIMO transmission, at each carrier frequency, TAE shall not exceed 90 ns | H16: For MIMO transmission, at each carrier frequency, TAE shall not exceed 65 ns.
A17: Occupied bandwidth | C17: TM1.1 | D17: MHz | E17: 98.28
A18: Adjacent channel leakage power | C18: TM1.1 TM1.2 | D18: dBc | E18: 43.8
A19: Operating band Unwanted emissions | C19: TM1.1 TM1.2 | D19: dBm | F19: 0 MHz ≤ Δf < 5 MHz: RBW 100 kHz < | G19: 0 MHz ≤ Δf < 5 MHz: RBW 100 kHz < | H19: 0 MHz ≤ Δf < 5 MHz: RBW 100 kHz <
C20: TM1.1 TM1.2 | D20: dBm | F20: 5 MHz ≤ Δf ≤ min (10 MHz, Δfmax): RBW 100 kHz < -12.2 dBm | G20: 6 MHz ≤ Δf ≤ min (10 MHz, Δfmax): RBW 100 kHz < -12.2 dBm | H20: 7 MHz ≤ Δf ≤ min (10 MHz, Δfmax): RBW 100 kHz < -12.2 dBm
C21: TM1.1 TM1.2 | D21: dBm | F21: 10 MHz ≤ Δf Δfmax: RBW 1 MHz < -15 dBm | G21: 11 MHz ≤ Δf Δfmax: RBW 1 MHz < -15 dBm | H21: 12 MHz ≤ Δf Δfmax: RBW 1 MHz < -15 dBm
A22: Transmitter intermodulation | B22: Adjacent channel leakage power | C22: TM1.1 | D22: dBc | E22: 43.8
B23: Operating band Unwanted emissions | C23: TM1.1 | D23: dBm | F23: 0 MHz ≤ Δf < 5 MHz: RBW 100 kHz < | G23: 0 MHz ≤ Δf < 5 MHz: RBW 100 kHz < | H23: 0 MHz ≤ Δf < 5 MHz: RBW 100 kHz <
C24: TM1.1 | D24: dBm | F24: 5 MHz ≤ Δf ≤ min (10 MHz, Δfmax): RBW 100 kHz < -12.2 dBm | G24: 6 MHz ≤ Δf ≤ min (10 MHz, Δfmax): RBW 100 kHz < -12.2 dBm | H24: 7 MHz ≤ Δf ≤ min (10 MHz, Δfmax): RBW 100 kHz < -12.2 dBm
C25: TM1.1 | D25: dBm | F25: 10 MHz ≤ Δf Δfmax: RBW 1 MHz < -15 dBm | G25: 11 MHz ≤ Δf Δfmax: RBW 1 MHz < -15 dBm | H25: 12 MHz ≤ Δf Δfmax: RBW 1 MHz < -15 dBm
B26: Transmitter spurious emission | C26: TM1.1 | D26: dBm
